Workbook
Name _Pic710: #N/A
Name _Pic810: #N/A
Name _Pic910: #N/A
Name a: [1]Input!#REF!
Name a: [1]Input!#REF!
Name a: [1]Input!#REF!
Name CEWS1: #REF!
Name CEWS1: #REF!
Name CEWS1: #REF!
Name CEWS10: #REF!
Name CEWS10: #REF!
Name CEWS11: #REF!
Name CEWS11: #REF!
Name CEWS12: #REF!
Name CEWS12: #REF!
Name CEWS13: #REF!
Name CEWS13: #REF!
Name CEWS14: #REF!
Name CEWS14: #REF!
Name CEWS15: #REF!
Name CEWS15: #REF!
Name CEWS2: #REF!
Name CEWS2: #REF!
Name CEWS3: #REF!
Name CEWS3: #REF!
Name CEWS4: #REF!
Name CEWS4: #REF!
Name CEWS5: #REF!
Name CEWS5: #REF!
Name CEWS6: #REF!
Name CEWS6: #REF!
Name CEWS7: #REF!
Name CEWS7: #REF!
Name CEWS8: #REF!
Name CEWS8: #REF!
Name CEWS9: #REF!
Name CEWS9: #REF!
Name CEWSH1: #REF!
Name CEWSH1: #REF!
Name CEWSH2: #REF!
Name CEWSH2: #REF!
Name CEWSH3: #REF!
Name CEWSH3: #REF!
Name CEWSH4: #REF!
Name CEWSH4: #REF!
Name CEWSH5: #REF!
Name CEWSH5: #REF!
Name CEWSMA1: #REF!
Name CEWSMA1: #REF!
Name CEWSMA2: #REF!
Name CEWSMA2: #REF!
Name CEWSMA3: #REF!
Name CEWSMA3: #REF!
Name CEWSMA4: #REF!
Name CEWSMA4: #REF!
Name CEWSMA5: #REF!
Name CEWSMA5: #REF!
Name CEWSME1: #REF!
Name CEWSME1: #REF!
Name CEWSME2: #REF!

Sheet IPS V4.1
B2: Initial Problem Solving (IPS)
B4: 1.1. Initiate IPS: Lakukan IPS jika terjadi losses besar/berulang atau salah satu pemicu berikut terpenuhi dan penyebab langsungnya tidak diketahui (Pemicu harus ditentukan secara lokal dan diikuti)
E6: Insiden Kualitas? | O6: Line: | P6: LU21-ID01 | V6: IPS ID:
E8: Stop berulang dalam satu shift (e.g. >20 times/shift, process failure >20 min)? | O8: Date:
E10: Waste atau Reject berulang dalam satu shift? atau Tren waste meningkat?
E12: Sporadic losses lainnya: ___________________________________________
C14: =C6&C8&C10&C12 | O14: Technology | V14: LE Champion PIC ID
C15: Note: Untuk isu terkait EHS, harus menggunakan IPS EHS
B17: INITIAL PROBLEM STATEMENT
B18: Message Stop/Loss Sesuai SPA/HMI | P18: Evidence/Failure Mode
B23: 1.2. Refocus the Problem: Selesaikan 6W2H untuk memfokuskan kembali masalah, berdasarkan apa yang sebenarnya diamati, bukan apa yang Anda duga terjadi.
B25: 1. What? | G25: Apa yang terjadi? Apa Fenomena yang di observasi? Jelaskan yang terjadi secara akurat sesuai yang dilihat (Bukan yang seharusnya terjadi) | R25: 2. Where? | U25: Dimana Terjadinya? Dimana Tidak Terjadi? (titik transformasi) Jelaskan indikasi se-detail mungkin terkait dimana masalah terjadi (dimana transformasi tempat masalah terjadi). Jelaskan titik mulai dan berakhirnya loss / poin penyebab, mengacu ke Equipment Transformation List & WPA untuk line yang sudah di AM Step 4.
B30: Gambar (Jika Mungkin) Fenomena yang di observasi (Kondisi Saat Ini) dan Kondisi ideal ditempat masalah terjadi
B31: Current | R31: Ideal
B38: 3. To Whom? | G38: Di Area, Line, System mana yang terkena efek? Tunjukan dampak masalah yang terjadi ke area mesin / equipment / line lainnya. Area / line / sistem mana yang terdampak? Lakukan pengecekkan ke line lain dengan brand/format/teknologi yang sama, untuk melihata apakah masalah yang sama juga muncul / terjadi. | R38: 4. How? | U38: Bagaimana masalah ini terjadi? (Keadaan sekitar terjadinya masalah) Deskripsikan detail flow proses di equipment transformation list, yang terkait dengan bukti / evidence yang ada. Misalnya: sebelum terjadi stop, apakah ada reject konsekutif, suara yang abnormal, speed yang naik turun, material misalignment? Apakah masalah terjadi saat mesin running di target speed?
B44: 5. Which? | G44: di Brand, SKU's, Format, Blend, Material apakah masalah terjadi? (atau yang tidak terjadi) Mohon spesifikkan di brand/SKU mana issue terjadi | R44: 6. When? | U44: Kapan masalah terjadi? Cek kondisi spesifik yang terjadi / intervensi yang dilakukan, sebelum masalah terjadi. Apakah masalah terjadi setelah start up / stop / shutdown, apakah saat ramp up speed, saat mesin running normal? Misalnya: setelah brand change / perbaikan DH / cleaning mesin / planned maintenance / dll....
B50: 7. Who? | G50: Di tim atau Orang manakah masalah terjadi? Siapakah yang mendeteksi masalah? Apakah masalah terjadi di shift sebelumnya? Jika iya, di tim yang mana? System/orang Mana yang mendeteksi masalah? | R50: 8. How Much? | U50: Define quantity and frequency. Cek apakah masalah terjadi hanya di saat-saat tertentu saja / secara terus-menerus? Jika terjadi hanya saat-saat tertentu saja, seberapa sering muncul nya? Apakah stop nya semakin bertambah / berkurang?
B56: NEW REFOCUSED PROBLEM STATEMENT Sekarang jelaskan se-detail mungkin masalah berdasarkan observasi lewat 6W2H (Apa yang terjadi secara fisik/ atau harusnya tidak terjadi) dan Periksa apa ada trouble shooting guide yang spesifik dengan masalah yang terjadi
B62: 1.3. Verify base condition for refocused problem (Mohon refer ke kolom "Where") | M62: 1.4. Restore Base Condition: Jika terjadi masalah pada sistem, silahkan isi table dibawah:
B64: OK: Standard tersedia, diperbarui dan diikuti NOK: Masalah pada sistem (standard tidak tersedia, tidak diikuti, tidak diperbarui) NA: Sistem tidak berlaku | M64: Standar mana yang tidak ada atau membutuhkan pembaruan? | T64: Tindakan untuk kembali ke standar / untuk memperbarui (*) | Y64: Responsible | AA64: Due date
C66: OK | E66: NOK | G66: NA | I66: AM Cleaning, Inspection and Lubrication (CIL): Periksa apakah area tersebut bersih dan komponen dilumasi sesuai standar. Apakah setiap tugas CIL yang terkait dengan masalah telah 100% dilakukan?
C68: OK | E68: NOK | G68: NA | I68: AM Defect Handling (DH): Apakah peralatan bebas dari defect? cek DH Log dan pastikan tidak ada komponen yang defect (misal. gauges tidak terkalibrasi, tipe baut yang salah dll.)
C70: OK | E70: NOK | G70: NA | I70: AM Centerlines (CL): Apakah semua CL sudah ada dan sesuai dengan target?
C72: OK | E72: NOK | G72: NA | I72: PM: Kegiatan Maintenance dieksekusi sesuai dengan standard?
C74: OK | E74: NOK | G74: NA | I74: WPI: Metode Operasi dilakukan sesuai standard (i.e. praktik kerja yang aman, kualitas sesuai). Visual control tidak menunjukan penyimpangan.
C76: OK | E76: NOK | G76: NA | I76: WPI: Aktifitas Changeover dieksekusi sesuai dengan standard?
C78: OK | E78: NOK | G78: NA | I78: Quality: Material bebas cacat dan sesuai spesifikasi? Apakah ada Quality flag di area yang bermasalah dan belum di close? Jika iya, apakah berdampak pada losses. (i.e. control system tidak bekerja, cacat visual pada produk, dll)
B80: * Before creating a new standard, please ensure that all the existing systems are in standard. Take into account that new standards will require additional validations not covered in IPS
B82: Initial Problem Solving (IPS)
B84: 1.5. Ask WHY WHY?: Tanyakan kenapa deviasi dari standard terjadi?
B85: WHAT? (Penyebab; semua yang terbukti "Benar/True") | I85: WHY? (1) Penyebab langsung yang ditemukan | J85: T/F | K85: WHY? (2) | L85: T/F | M85: WHY? (3) | S85: T/F | T85: WHY? (4) | U85: T/F | V85: WHY? (5) | W85: T/F | X85: CAUNTERMEASURES (Jika action untuk pembuatan standard baru seperti CL, CIL sudah di buat, tambahkan link Digiperf nya juga) | Y85: Responsible | Z85: Due Date | AA85: Reapplicable (Y/N)
AE88: =IF(AA88<>"",AA88,"") | AF88: =IF(AE88<>"","("&AE88&") "&AD88,"") | AH88: =IF(AG88<>"","("&AG88&") "&AF88,"") | AM88: =_xlfn.TEXTJOIN(CHAR(10),TRUE,AF88:AF139) | BF88: =IF(X88<>"",X88,"") | BG88: =IF(AA88="Y","("&AA88&")"&" "&BF88,"") | BH88: =_xlfn.TEXTJOIN(CHAR(10),TRUE,BG88:BG140)
AD97: =IF(X97<>"",X97,"") | AE97: =IF(AA97<>"",AA97,"") | AF97: =IF(AE97<>"","("&AE97&") "&AD97,"") | BF97: =IF(X97<>"",X97,"") | BG97: =IF(AA97="Y","("&AA97&")"&" "&BF97,"")
AD106: =IF(X106<>"",X106,"") | AE106: =IF(AA106<>"",AA106,"") | AF106: =IF(AE106<>"","("&AE106&") "&AD106,"") | BF106: =IF(X106<>"",X106,"") | BG106: =IF(AA106="Y","("&AA106&")"&" "&BF106,"")
AD115: =IF(X115<>"",X115,"") | AE115: =IF(AA115<>"",AA115,"") | AF115: =IF(AE115<>"","("&AE115&") "&AD115,"") | BF115: =IF(X115<>"",X115,"") | BG115: =IF(AA115="Y","("&AA115&")"&" "&BF115,"")
AD124: =IF(X124<>"",X124,"") | AE124: =IF(AA124<>"",AA124,"") | AF124: =IF(AE124<>"","("&AE124&") "&AD124,"") | BF124: =IF(X124<>"",X124,"") | BG124: =IF(AA124="Y","("&AA124&")"&" "&BF124,"")
AD133: =IF(X133<>"",X133,"") | AE133: =IF(AA133<>"",AA133,"") | AF133: =IF(AE133<>"","("&AE133&") "&AD133,"") | BF133: =IF(X133<>"",X133,"") | BG133: =IF(AA133="Y","("&AA133&")"&" "&BF133,"")
B142: 1.6. Check the Quality of the IPS: Untuk memutuskan apakah IPS ditutup atau perlu dilakukan UPS (Dilakukan oleh EO dengan Process Lead)
B144: Leader owning completion: | U144: Date of completion:
B146: IPS Summary and next steps
...

Sheet BCC List
A1: DETAIL PENGECEKAN BCC IPS
A2: No | B2: Date | C2: Shift | D2: DMS/SWP | E2: Item Check | F2: Std | G2: Actual cek | H2: PIC | I2: Status (restore to basic condition) | J2: Apakah berimpact? | L2: {=IFERROR(INDEX(D$5:D$49,SMALL(IF(E$5:E$49<>"",ROW(D$5:D$49)-ROW(D$5)+1),ROWS(D$5:D5))),"")} | M2: {=IFERROR(INDEX(E$5:E$49,SMALL(IF(D$5:D$49<>"",ROW(E$5:E$49)-ROW(E$5)+1),ROWS(E$5:E5))),"")} | N2: =IF(L2<>"","("&L2&")","") | O2: =N2&" "&M2 | Q2: =_xlfn.TEXTJOIN(CHAR(10),TRUE,O2:O7)
L3: {=IFERROR(INDEX(D$5:D$49,SMALL(IF(E$5:E$49<>"",ROW(D$5:D$49)-ROW(D$5)+1),ROWS(D$5:D6))),"")} | M3: {=IFERROR(INDEX(E$5:E$49,SMALL(IF(D$5:D$49<>"",ROW(E$5:E$49)-ROW(E$5)+1),ROWS(E$5:E6))),"")} | N3: =IF(L3<>"","("&L3&")","") | O3: =N3&" "&M3
L4: {=IFERROR(INDEX(D$5:D$49,SMALL(IF(E$5:E$49<>"",ROW(D$5:D$49)-ROW(D$5)+1),ROWS(D$5:D6))),"")} | M4: {=IFERROR(INDEX(E$5:E$49,SMALL(IF(D$5:D$49<>"",ROW(E$5:E$49)-ROW(E$5)+1),ROWS(E$5:E6))),"")} | N4: =IF(L4<>"","("&L4&")","") | O4: =N4&" "&M4
L5: {=IFERROR(INDEX(D$5:D$49,SMALL(IF(E$5:E$49<>"",ROW(D$5:D$49)-ROW(D$5)+1),ROWS(D$5:D6))),"")} | M5: {=IFERROR(INDEX(E$5:E$49,SMALL(IF(D$5:D$49<>"",ROW(E$5:E$49)-ROW(E$5)+1),ROWS(E$5:E6))),"")} | N5: =IF(L5<>"","("&L5&")","") | O5: =N5&" "&M5
L6: {=IFERROR(INDEX(D$5:D$49,SMALL(IF(E$5:E$49<>"",ROW(D$5:D$49)-ROW(D$5)+1),ROWS(D$5:D7))),"")} | M6: {=IFERROR(INDEX(E$5:E$49,SMALL(IF(D$5:D$49<>"",ROW(E$5:E$49)-ROW(E$5)+1),ROWS(E$5:E7))),"")} | N6: =IF(L6<>"","("&L6&")","") | O6: =N6&" "&M6
L7: {=IFERROR(INDEX(D$5:D$49,SMALL(IF(E$5:E$49<>"",ROW(D$5:D$49)-ROW(D$5)+1),ROWS(D$5:D8))),"")}
L8: {=IFERROR(INDEX(D$5:D$49,SMALL(IF(E$5:E$49<>"",ROW(D$5:D$49)-ROW(D$5)+1),ROWS(D$5:D9))),"")}
L9: {=IFERROR(INDEX(D$5:D$49,SMALL(IF(E$5:E$49<>"",ROW(D$5:D$49)-ROW(D$5)+1),ROWS(D$5:D10))),"")}
L10: {=IFERROR(INDEX(D$5:D$49,SMALL(IF(E$5:E$49<>"",ROW(D$5:D$49)-ROW(D$5)+1),ROWS(D$5:D11))),"")}
L11: {=IFERROR(INDEX(D$5:D$49,SMALL(IF(E$5:E$49<>"",ROW(D$5:D$49)-ROW(D$5)+1),ROWS(D$5:D12))),"")}
L12: {=IFERROR(INDEX(D$5:D$49,SMALL(IF(E$5:E$49<>"",ROW(D$5:D$49)-ROW(D$5)+1),ROWS(D$5:D13))),"")}
L13: {=IFERROR(INDEX(D$5:D$49,SMALL(IF(E$5:E$49<>"",ROW(D$5:D$49)-ROW(D$5)+1),ROWS(D$5:D14))),"")}
L14: {=IFERROR(INDEX(D$5:D$49,SMALL(IF(E$5:E$49<>"",ROW(D$5:D$49)-ROW(D$5)+1),ROWS(D$5:D15))),"")} | M14: {=IFERROR(INDEX(E$5:E$49,SMALL(IF(D$5:D$49<>"",ROW(E$5:E$49)-ROW(E$5)+1),ROWS(E$5:E15))),"")} | N14: =IF(L14<>"","("&L14&")","") | O14: =N14&" "&M14
L15: {=IFERROR(INDEX(D$5:D$49,SMALL(IF(E$5:E$49<>"",ROW(D$5:D$49)-ROW(D$5)+1),ROWS(D$5:D16))),"")} | M15: {=IFERROR(INDEX(E$5:E$49,SMALL(IF(D$5:D$49<>"",ROW(E$5:E$49)-ROW(E$5)+1),ROWS(E$5:E16))),"")} | N15: =IF(L15<>"","("&L15&")","") | O15: =N15&" "&M15
L16: {=IFERROR(INDEX(D$5:D$49,SMALL(IF(E$5:E$49<>"",ROW(D$5:D$49)-ROW(D$5)+1),ROWS(D$5:D17))),"")} | M16: {=IFERROR(INDEX(E$5:E$49,SMALL(IF(D$5:D$49<>"",ROW(E$5:E$49)-ROW(E$5)+1),ROWS(E$5:E17))),"")} | N16: =IF(L16<>"","("&L16&")","") | O16: =N16&" "&M16
L17: {=IFERROR(INDEX(D$5:D$49,SMALL(IF(E$5:E$49<>"",ROW(D$5:D$49)-ROW(D$5)+1),ROWS(D$5:D18))),"")} | M17: {=IFERROR(INDEX(E$5:E$49,SMALL(IF(D$5:D$49<>"",ROW(E$5:E$49)-ROW(E$5)+1),ROWS(E$5:E18))),"")} | N17: =IF(L17<>"","("&L17&")","") | O17: =N17&" "&M17
L18: {=IFERROR(INDEX(D$5:D$49,SMALL(IF(E$5:E$49<>"",ROW(D$5:D$49)-ROW(D$5)+1),ROWS(D$5:D19))),"")} | M18: {=IFERROR(INDEX(E$5:E$49,SMALL(IF(D$5:D$49<>"",ROW(E$5:E$49)-ROW(E$5)+1),ROWS(E$5:E19))),"")} | N18: =IF(L18<>"","("&L18&")","") | O18: =N18&" "&M18
L19: {=IFERROR(INDEX(D$5:D$49,SMALL(IF(E$5:E$49<>"",ROW(D$5:D$49)-ROW(D$5)+1),ROWS(D$5:D20))),"")} | M19: {=IFERROR(INDEX(E$5:E$49,SMALL(IF(D$5:D$49<>"",ROW(E$5:E$49)-ROW(E$5)+1),ROWS(E$5:E20))),"")} | N19: =IF(L19<>"","("&L19&")","") | O19: =N19&" "&M19
L20: {=IFERROR(INDEX(D$5:D$49,SMALL(IF(E$5:E$49<>"",ROW(D$5:D$49)-ROW(D$5)+1),ROWS(D$5:D21))),"")} | M20: {=IFERROR(INDEX(E$5:E$49,SMALL(IF(D$5:D$49<>"",ROW(E$5:E$49)-ROW(E$5)+1),ROWS(E$5:E21))),"")} | N20: =IF(L20<>"","("&L20&")","") | O20: =N20&" "&M20
L21: {=IFERROR(INDEX(D$5:D$49,SMALL(IF(E$5:E$49<>"",ROW(D$5:D$49)-ROW(D$5)+1),ROWS(D$5:D22))),"")} | M21: {=IFERROR(INDEX(E$5:E$49,SMALL(IF(D$5:D$49<>"",ROW(E$5:E$49)-ROW(E$5)+1),ROWS(E$5:E22))),"")} | N21: =IF(L21<>"","("&L21&")","") | O21: =N21&" "&M21
L22: {=IFERROR(INDEX(D$5:D$49,SMALL(IF(E$5:E$49<>"",ROW(D$5:D$49)-ROW(D$5)+1),ROWS(D$5:D23))),"")} | M22: {=IFERROR(INDEX(E$5:E$49,SMALL(IF(D$5:D$49<>"",ROW(E$5:E$49)-ROW(E$5)+1),ROWS(E$5:E23))),"")} | N22: =IF(L22<>"","("&L22&")","") | O22: =N22&" "&M22
L23: {=IFERROR(INDEX(D$5:D$49,SMALL(IF(E$5:E$49<>"",ROW(D$5:D$49)-ROW(D$5)+1),ROWS(D$5:D24))),"")} | M23: {=IFERROR(INDEX(E$5:E$49,SMALL(IF(D$5:D$49<>"",ROW(E$5:E$49)-ROW(E$5)+1),ROWS(E$5:E24))),"")} | N23: =IF(L23<>"","("&L23&")","") | O23: =N23&" "&M23
L24: {=IFERROR(INDEX(D$5:D$49,SMALL(IF(E$5:E$49<>"",ROW(D$5:D$49)-ROW(D$5)+1),ROWS(D$5:D25))),"")} | M24: {=IFERROR(INDEX(E$5:E$49,SMALL(IF(D$5:D$49<>"",ROW(E$5:E$49)-ROW(E$5)+1),ROWS(E$5:E25))),"")} | N24: =IF(L24<>"","("&L24&")","") | O24: =N24&" "&M24
L25: {=IFERROR(INDEX(D$5:D$49,SMALL(IF(E$5:E$49<>"",ROW(D$5:D$49)-ROW(D$5)+1),ROWS(D$5:D26))),"")} | M25: {=IFERROR(INDEX(E$5:E$49,SMALL(IF(D$5:D$49<>"",ROW(E$5:E$49)-ROW(E$5)+1),ROWS(E$5:E26))),"")} | N25: =IF(L25<>"","("&L25&")","") | O25: =N25&" "&M25
... L49: {=IFERROR(INDEX(D$5:D$49,SMALL(IF(E$5:E$49<>"",ROW(D$5:D$49)-ROW(D$5)+1),ROWS(D$5:D50))),"")} | M49: {=IFERROR(INDEX(E$5:E$49,SMALL(IF(D$5:D$49<>"",ROW(E$5:E$49)-ROW(E$5)+1),ROWS(E$5:E50))),"")} | N49: =IF(L49<>"","("&L49&")","") | O49: =N49&" "&M49

Sheet Extraction
D3: Submission Date | E3: Dept | F3: LU | G3: Technology | H3: Loss Category | I3: Loss Name | J3: Evidence | K3: What | L3: Where | M3: To Whom | N3: How | O3: Which | P3: When | Q3: Who | R3: How Much | S3: Refocused Problem Statement | T3: BCC NoK List | U3: BCC NoK List Action | V3: Countermeasure | W3: All BCC List | X3: CM to RM | Y3: Impact Cost
D4: ='IPS V4.1'!P8 -> 0 | E4: =IF(RIGHT(F4,SEARCH("-",F4,1)-1)="ID01","SPM",IF(RIGHT(F4,SEARCH("-",F4,1)-1)="ID02","SKM",IF(RIGHT(F4,SEARCH("-",F4,1)-1)="ID30","RRP",""))) -> SPM | F4: ='IPS V4.1'!P6 -> LU21-ID01 | G4: ='IPS V4.1'!Q14 -> 0 | H4: ='IPS V4.1'!C14 | I4: ='IPS V4.1'!B19 -> 0 | J4: ='IPS V4.1'!P19 -> 0 | K4: =IF('IPS V4.1'!B26="","",'IPS V4.1'!B26) | L4: =IF('IPS V4.1'!R26="","",'IPS V4.1'!R26) | M4: =IF('IPS V4.1'!B39="","",'IPS V4.1'!B39) | N4: =IF('IPS V4.1'!R39="","",'IPS V4.1'!R39) | O4: =IF('IPS V4.1'!B45="","",'IPS V4.1'!B45) | P4: =IF('IPS V4.1'!R45="","",'IPS V4.1'!R45) | Q4: =IF('IPS V4.1'!B51="","",'IPS V4.1'!B51) | R4: =IF('IPS V4.1'!R51="","",'IPS V4.1'!R51) | S4: =IF('IPS V4.1'!B57="","",'IPS V4.1'!B57) | T4: ='IPS V4.1'!M66&CHAR(10)&'IPS V4.1'!M68&CHAR(10)&'IPS V4.1'!M70&CHAR(10)&'IPS V4.1'!M72&CHAR(10)&'IPS V4.1'!M74&CHAR(10)&'IPS V4.1'!M76&CHAR(10)&'IPS V4.1'!M78 | U4: ='IPS V4.1'!T66&CHAR(10)&'IPS V4.1'!T68&CHAR(10)&'IPS V4.1'!T70&CHAR(10)&'IPS V4.1'!T72&CHAR(10)&'IPS V4.1'!T74&CHAR(10)&'IPS V4.1'!T76&CHAR(10)&'IPS V4.1'!T78 | V4: ='IPS V4.1'!AM88 | W4: ='BCC List'!Q2 | X4: =IF('IPS V4.1'!BH88="","",'IPS V4.1'!BH88) | Y4: =SUM('Cost Impact Calculator'!B28:B30) -> 0

Sheet LE Champion Tracking
E5: LE Champion Name
E6: ='IPS V4.1'!X14 -> 0

Sheet Cost Impact Calculator
A1: Cost Dictionary
A2: Delivery | E2: Cost
A3: Linkup | B3: Sensitivity 1% Yearly IDR | C3: Format | E3: Linkup | F3: Cigarette | G3: Cost Pack | H3: Format | I3: Pack
A4: LU12-ID02 | B4: 30364427 | C4: 16 | E4: LU12-ID02 | F4: 10.67 | G4: =H4*I4 -> 320.32 | H4: 16 | I4: 20.02
A5: LU14-ID02 | B5: 19205853 | C5: 20 | E5: LU14-ID02 | F5: 8.5 | G5: =H5*I5 -> 484 | H5: 20 | I5: 24.2
A6: LU15-ID02 | B6: 29521195 | C6: 16 | E6: LU15-ID02 | F6: 10.67 | G6: =H6*I6 -> 320.32 | H6: 16 | I6: 20.02
A7: LU16-ID02 | B7: 18012651 | C7: 16 | E7: LU16-ID02 | F7: 10.67 | G7: =H7*I7 -> 320.32 | H7: 16 | I7: 20.02
A8: LU17-ID02 | B8: 29337262 | C8: 16 | E8: LU17-ID02 | F8: 10.67 | G8: =H8*I8 -> 320.32 | H8: 16 | I8: 20.02
A9: LU10-ID02 | B9: 20003958 | C9: 10 | E9: LU10-ID02 | F9: 12.36 | G9: =H9*I9 -> 263.8 | H9: 10 | I9: 26.38
A10: LU11-ID02 | B10: 20224688 | C10: 10 | E10: LU11-ID02 | F10: 12.36 | G10: =H10*I10 -> 263.8 | H10: 10 | I10: 26.38
A11: LU25-ID02 | B11: 23925754 | C11: 16 | E11: LU25-ID02 | F11: 10.67 | G11: =H11*I11 -> 320.32 | H11: 16 | I11: 20.02
A12: LU26-ID02 | B12: 18512972 | C12: 16 | E12: LU26-ID02 | F12: 10.67 | G12: =H12*I12 -> 320.32 | H12: 16 | I12: 20.02
A13: LU27-ID02 | B13: 28230115 | C13: 16 | E13: LU27-ID02 | F13: 10.67 | G13: =H13*I13 -> 320.32 | H13: 16 | I13: 20.02
A14: LU11-ID01 | B14: 11530581 | C14: 20 | E14: LU11-ID01 | F14: 10.9 | G14: =H14*I14 -> 402 | H14: 20 | I14: 20.1
A15: LU12-ID01 | B15: 17298597 | C15: 20 | E15: LU12-ID01 | F15: 46.2 | G15: =H15*I15 -> 1202 | H15: 20 | I15: 60.1
... A26: LU24-ID01 | B26: 57886243 | C26: 20 | E26: LU24-ID01 | F26: 10.9 | G26: =H26*I26 -> 402 | H26: 20 | I26: 20.1
A28: ='IPS V4.1'!P6 -> LU21-ID01 | B28: =IF('IPS V4.1'!C14="D",'IPS V4.1'!X148*VLOOKUP(A28,A2:C26,2,FALSE)*VLOOKUP(A28,A2:C26,3,FALSE)*20160/525600,"") | C28: D
B29: =IF(AND('IPS V4.1'!C14="C",OR('IPS V4.1'!Q14="GD121",'IPS V4.1'!Q14="PM100",'IPS V4.1'!Q14="M8")),'IPS V4.1'!X150*VLOOKUP(A28,E4:G26,2,FALSE),IF(AND('IPS V4.1'!C14="C",OR('IPS V4.1'!Q14<>"GD121",'IPS V4.1'!Q14="PM100",'IPS V4.1'!Q14="M8")),'IPS V4.1'!X150*VLOOKUP(A28,E4:G26,3,FALSE),"")) | C29: C
B30: ='IPS V4.1'!X152 -> 0 | C30: Q
B31: =VLOOKUP(A28,A2:C26,3,FALSE) -> 20 | C31: Format
